testcase.txt
Testcase 1:

PLACE SELL LIMIT 100 5
PLACE SELL LIMIT 101 10
PLACE BUY LIMIT 99 5
PLACE BUY LIMIT 98 10
MODIFY 4 PRICE 100
MODIFY 4 QTY 7
CANCEL 2
PLACE SELL LIMIT 102 10
PLACE BUY MARKET 0 5
PLACE BUY MARKET 0 12
PLACE SELL MARKET 0 4
PLACE BUY LIMIT 102 3
MODIFY 3 PRICE 102
MODIFY 3 QTY 10
PLACE SELL LIMIT 102 5
PLACE SELL MARKET 0 5
PLACE BUY MARKET 0 5
PLACE SELL MARKET 0 5
EXIT



Testcase 2:

PLACE SELL LIMIT 105 10
PLACE SELL LIMIT 106 5
PLACE BUY LIMIT 100 15
PLACE BUY LIMIT 99 20
PLACE BUY LIMIT 104 3
PLACE SELL LIMIT 103 6
PLACE BUY MARKET 0 8
PLACE SELL MARKET 0 10
MODIFY 2 PRICE 102
MODIFY 2 QTY 10
CANCEL 4
PLACE SELL LIMIT 98 5
PLACE BUY LIMIT 97 5
PLACE SELL LIMIT 97 10
MODIFY 10 PRICE 98
MODIFY 10 QTY 8
CANCEL 6
PLACE BUY MARKET 0 12
PLACE SELL MARKET 0 3
PLACE SELL LIMIT 99 5
PLACE BUY LIMIT 99 5
PLACE SELL LIMIT 101 7
MODIFY 16 PRICE 99
PLACE BUY LIMIT 101 7
PLACE SELL MARKET 0 7
CANCEL 1
PLACE BUY LIMIT 110 10
PLACE SELL LIMIT 109 4
PLACE SELL LIMIT 110 3
PLACE SELL LIMIT 111 5
MODIFY 22 PRICE 108
MODIFY 22 QTY 10
CANCEL 21
PLACE BUY LIMIT 108 5
PLACE SELL LIMIT 100 10
PLACE BUY MARKET 0 15
PLACE SELL LIMIT 100 10
PLACE BUY MARKET 0 15
EXIT
